Workbook

Sheet MEGA SENA
A1: Concurso | B1: Data do Sorteio | C1: Bola1 | D1: Bola2 | E1: Bola3 | F1: Bola4 | G1: Bola5 | H1: Bola6 | I1: Bola7 | J1: repetições | K1: Ganhadores 6 acertos | L1: Mod 1 | M1: Mod 2 | N1: Mod 3 | O1: Mod 4 | P1: Mod 5 | Q1: Mod 6 | R1: Max Mod 1 | S1: Max Mod 2 | T1: Max Mod 3 | U1: Max Mod 4 | V1: Max Mod 5 | W1: Max Mod 6
A2: 1 | B2: 11/03/1996 | C2: 4 | D2: 5 | E2: 30 | F2: 33 | G2: 41 | H2: 52 | I2: =RIGHT(("0"&C2),2)&RIGHT(("0"&D2),2)&RIGHT(("0"&E2),2)&RIGHT(("0"&F2),2)&RIGHT(("0"&G2),2)&RIGHT(("0"&H2),2) -> 040530334152 | J2: =COUNTIF(I:I,I2) -> 1 | K2: 0 | L2: =VLOOKUP(C2,bola01!A:E,5,0) -> 6 | M2: =VLOOKUP(D2,bola02!A:E,5,0) -> 5 | N2: =VLOOKUP(E2,bola03!A:E,5,0) -> 0 | O2: =VLOOKUP(F2,bola04!A:E,5,0) -> 0 | P2: =VLOOKUP(G2,bola05!A:E,5,0) -> 2 | Q2: =VLOOKUP(H2,bola06!A:E,5,0) -> 3 | R2: =MAX(bola01!E:E) -> 6 | S2: =MAX(bola02!E:E) -> 6 | T2: =MAX(bola03!E:E) -> 6 | U2: =MAX(bola04!E:E) -> 6 | V2: =MAX(bola05!E:E) -> 6 | W2: =MAX(bola06!E:E) -> 6
A3: 2 | B3: 18/03/1996 | C3: 9 | D3: 37 | E3: 39 | F3: 41 | G3: 43 | H3: 49 | I3: =RIGHT(("0"&C3),2)&RIGHT(("0"&D3),2)&RIGHT(("0"&E3),2)&RIGHT(("0"&F3),2)&RIGHT(("0"&G3),2)&RIGHT(("0"&H3),2) -> 093739414349 | J3: =COUNTIF(I:I,I3) -> 1 | K3: 1 | L3: =VLOOKUP(C3,bola01!A:E,5,0) -> 6 | M3: =VLOOKUP(D3,bola02!A:E,5,0) -> 4 | N3: =VLOOKUP(E3,bola03!A:E,5,0) -> 2 | O3: =VLOOKUP(F3,bola04!A:E,5,0) -> 5 | P3: =VLOOKUP(G3,bola05!A:E,5,0) -> 3 | Q3: =VLOOKUP(H3,bola06!A:E,5,0) -> 5 | R3: =MAX(bola01!E:E) -> 6 | S3: =MAX(bola02!E:E) -> 6 | T3: =MAX(bola03!E:E) -> 6 | U3: =MAX(bola04!E:E) -> 6 | V3: =MAX(bola05!E:E) -> 6 | W3: =MAX(bola06!E:E) -> 6
A4: 3 | B4: 25/03/1996 | C4: 10 | D4: 11 | E4: 29 | F4: 30 | G4: 36 | H4: 47 | I4: =RIGHT(("0"&C4),2)&RIGHT(("0"&D4),2)&RIGHT(("0"&E4),2)&RIGHT(("0"&F4),2)&RIGHT(("0"&G4),2)&RIGHT(("0"&H4),2) -> 101129303647 | J4: =COUNTIF(I:I,I4) -> 1 | K4: 2 | L4: =VLOOKUP(C4,bola01!A:E,5,0) -> 5 | M4: =VLOOKUP(D4,bola02!A:E,5,0) -> 5 | N4: =VLOOKUP(E4,bola03!A:E,5,0) -> 4 | O4: =VLOOKUP(F4,bola04!A:E,5,0) -> 6 | P4: =VLOOKUP(G4,bola05!A:E,5,0) -> 2 | Q4: =VLOOKUP(H4,bola06!A:E,5,0) -> 0 | R4: =MAX(bola01!E:E) -> 6 | S4: =MAX(bola02!E:E) -> 6 | T4: =MAX(bola03!E:E) -> 6 | U4: =MAX(bola04!E:E) -> 6 | V4: =MAX(bola05!E:E) -> 6 | W4: =MAX(bola06!E:E) -> 6
A5: 4 | B5: 01/04/1996 | C5: 1 | D5: 5 | E5: 6 | F5: 27 | G5: 42 | H5: 59 | I5: =RIGHT(("0"&C5),2)&RIGHT(("0"&D5),2)&RIGHT(("0"&E5),2)&RIGHT(("0"&F5),2)&RIGHT(("0"&G5),2)&RIGHT(("0"&H5),2) -> 010506274259 | J5: =COUNTIF(I:I,I5) -> 1 | K5: 0 | L5: =VLOOKUP(C5,bola01!A:E,5,0) -> 2 | M5: =VLOOKUP(D5,bola02!A:E,5,0) -> 5 | N5: =VLOOKUP(E5,bola03!A:E,5,0) -> 6 | O5: =VLOOKUP(F5,bola04!A:E,5,0) -> 6 | P5: =VLOOKUP(G5,bola05!A:E,5,0) -> 1 | Q5: =VLOOKUP(H5,bola06!A:E,5,0) -> 5 | R5: =MAX(bola01!E:E) -> 6 | S5: =MAX(bola02!E:E) -> 6 | T5: =MAX(bola03!E:E) -> 6 | U5: =MAX(bola04!E:E) -> 6 | V5: =MAX(bola05!E:E) -> 6 | W5: =MAX(bola06!E:E) -> 6
A6: 5 | B6: 08/04/1996 | C6: 1 | D6: 2 | E6: 6 | F6: 16 | G6: 19 | H6: 46 | I6: =RIGHT(("0"&C6),2)&RIGHT(("0"&D6),2)&RIGHT(("0"&E6),2)&RIGHT(("0"&F6),2)&RIGHT(("0"&G6),2)&RIGHT(("0"&H6),2) -> 010206161946 | J6: =COUNTIF(I:I,I6) -> 1 | K6: 0 | L6: =VLOOKUP(C6,bola01!A:E,5,0) -> 2 | M6: =VLOOKUP(D6,bola02!A:E,5,0) -> 6 | N6: =VLOOKUP(E6,bola03!A:E,5,0) -> 6 | O6: =VLOOKUP(F6,bola04!A:E,5,0) -> 2 | P6: =VLOOKUP(G6,bola05!A:E,5,0) -> 6 | Q6: =VLOOKUP(H6,bola06!A:E,5,0) | R6: =MAX(bola01!E:E) -> 6 | S6: =MAX(bola02!E:E) -> 6 | T6: =MAX(bola03!E:E) -> 6 | U6: =MAX(bola04!E:E) -> 6 | V6: =MAX(bola05!E:E) -> 6 | W6: =MAX(bola06!E:E) -> 6
A7: 6 | B7: 15/04/1996 | C7: 7 | D7: 13 | E7: 19 | F7: 22 | G7: 40 | H7: 47 | I7: =RIGHT(("0"&C7),2)&RIGHT(("0"&D7),2)&RIGHT(("0"&E7),2)&RIGHT(("0"&F7),2)&RIGHT(("0"&G7),2)&RIGHT(("0"&H7),2) -> 071319224047 | J7: =COUNTIF(I:I,I7) -> 1 | K7: 0 | L7: =VLOOKUP(C7,bola01!A:E,5,0) -> 0 | M7: =VLOOKUP(D7,bola02!A:E,5,0) -> 4 | N7: =VLOOKUP(E7,bola03!A:E,5,0) -> 1 | O7: =VLOOKUP(F7,bola04!A:E,5,0) | P7: =VLOOKUP(G7,bola05!A:E,5,0) -> 2 | Q7: =VLOOKUP(H7,bola06!A:E,5,0) -> 0 | R7: =MAX(bola01!E:E) -> 6 | S7: =MAX(bola02!E:E) -> 6 | T7: =MAX(bola03!E:E) -> 6 | U7: =MAX(bola04!E:E) -> 6 | V7: =MAX(bola05!E:E) -> 6 | W7: =MAX(bola06!E:E) -> 6
A8: 7 | B8: 22/04/1996 | C8: 3 | D8: 5 | E8: 20 | F8: 21 | G8: 38 | H8: 56 | I8: =RIGHT(("0"&C8),2)&RIGHT(("0"&D8),2)&RIGHT(("0"&E8),2)&RIGHT(("0"&F8),2)&RIGHT(("0"&G8),2)&RIGHT(("0"&H8),2) -> 030520213856 | J8: =COUNTIF(I:I,I8) -> 1 | K8: 0 | L8: =VLOOKUP(C8,bola01!A:E,5,0) -> 1 | M8: =VLOOKUP(D8,bola02!A:E,5,0) -> 5 | N8: =VLOOKUP(E8,bola03!A:E,5,0) -> 2 | O8: =VLOOKUP(F8,bola04!A:E,5,0) -> 5 | P8: =VLOOKUP(G8,bola05!A:E,5,0) -> 1 | Q8: =VLOOKUP(H8,bola06!A:E,5,0) -> 1 | R8: =MAX(bola01!E:E) -> 6 | S8: =MAX(bola02!E:E) -> 6 | T8: =MAX(bola03!E:E) -> 6 | U8: =MAX(bola04!E:E) -> 6 | V8: =MAX(bola05!E:E) -> 6 | W8: =MAX(bola06!E:E) -> 6
A9: 8 | B9: 29/04/1996 | C9: 4 | D9: 17 | E9: 37 | F9: 38 | G9: 47 | H9: 53 | I9: =RIGHT(("0"&C9),2)&RIGHT(("0"&D9),2)&RIGHT(("0"&E9),2)&RIGHT(("0"&F9),2)&RIGHT(("0"&G9),2)&RIGHT(("0"&H9),2) -> 041737384753 | J9: =COUNTIF(I:I,I9) -> 1 | K9: 0 | L9: =VLOOKUP(C9,bola01!A:E,5,0) -> 6 | M9: =VLOOKUP(D9,bola02!A:E,5,0) -> 3 | N9: =VLOOKUP(E9,bola03!A:E,5,0) -> 5 | O9: =VLOOKUP(F9,bola04!A:E,5,0) -> 3 | P9: =VLOOKUP(G9,bola05!A:E,5,0) -> 6 | Q9: =VLOOKUP(H9,bola06!A:E,5,0) -> 0 | R9: =MAX(bola01!E:E) -> 6 | S9: =MAX(bola02!E:E) -> 6 | T9: =MAX(bola03!E:E) -> 6 | U9: =MAX(bola04!E:E) -> 6 | V9: =MAX(bola05!E:E) -> 6 | W9: =MAX(bola06!E:E) -> 6
A10: 9 | B10: 06/05/1996 | C10: 8 | D10: 43 | E10: 54 | F10: 55 | G10: 56 | H10: 60 | I10: =RIGHT(("0"&C10),2)&RIGHT(("0"&D10),2)&RIGHT(("0"&E10),2)&RIGHT(("0"&F10),2)&RIGHT(("0"&G10),2)&RIGHT(("0"&H10),2) -> 084354555660 | J10: =COUNTIF(I:I,I10) -> 1 | K10: 0 | L10: =VLOOKUP(C10,bola01!A:E,5,0) -> 0 | M10: =VLOOKUP(D10,bola02!A:E,5,0) -> 5 | N10: =VLOOKUP(E10,bola03!A:E,5,0) -> 2 | O10: =VLOOKUP(F10,bola04!A:E,5,0) -> 0 | P10: =VLOOKUP(G10,bola05!A:E,5,0) -> 2 | Q10: =VLOOKUP(H10,bola06!A:E,5,0) | R10: =MAX(bola01!E:E) -> 6 | S10: =MAX(bola02!E:E) -> 6 | T10: =MAX(bola03!E:E) -> 6 | U10: =MAX(bola04!E:E) -> 6 | V10: =MAX(bola05!E:E) -> 6 | W10: =MAX(bola06!E:E) -> 6
A11: 10 | B11: 13/05/1996 | C11: 4 | D11: 18 | E11: 21 | F11: 25 | G11: 38 | H11: 57 | I11: =RIGHT(("0"&C11),2)&RIGHT(("0"&D11),2)&RIGHT(("0"&E11),2)&RIGHT(("0"&F11),2)&RIGHT(("0"&G11),2)&RIGHT(("0"&H11),2) -> 041821253857 | J11: =COUNTIF(I:I,I11) -> 1 | K11: 0 | L11: =VLOOKUP(C11,bola01!A:E,5,0) -> 6 | M11: =VLOOKUP(D11,bola02!A:E,5,0) -> 4 | N11: =VLOOKUP(E11,bola03!A:E,5,0) -> 3 | O11: =VLOOKUP(F11,bola04!A:E,5,0) -> 0 | P11: =VLOOKUP(G11,bola05!A:E,5,0) -> 1 | Q11: =VLOOKUP(H11,bola06!A:E,5,0) -> 2 | R11: =MAX(bola01!E:E) -> 6 | S11: =MAX(bola02!E:E) -> 6 | T11: =MAX(bola03!E:E) -> 6 | U11: =MAX(bola04!E:E) -> 6 | V11: =MAX(bola05!E:E) -> 6 | W11: =MAX(bola06!E:E) -> 6
A12: 11 | B12: 20/05/1996 | C12: 15 | D12: 25 | E12: 37 | F12: 38 | G12: 58 | H12: 59 | I12: =RIGHT(("0"&C12),2)&RIGHT(("0"&D12),2)&RIGHT(("0"&E12),2)&RIGHT(("0"&F12),2)&RIGHT(("0"&G12),2)&RIGHT(("0"&H12),2) -> 152537385859 | J12: =COUNTIF(I:I,I12) -> 1 | K12: 1 | L12: =VLOOKUP(C12,bola01!A:E,5,0) -> 6 | M12: =VLOOKUP(D12,bola02!A:E,5,0) -> 4 | N12: =VLOOKUP(E12,bola03!A:E,5,0) -> 5 | O12: =VLOOKUP(F12,bola04!A:E,5,0) -> 3 | P12: =VLOOKUP(G12,bola05!A:E,5,0) -> 4 | Q12: =VLOOKUP(H12,bola06!A:E,5,0) -> 5 | R12: =MAX(bola01!E:E) -> 6 | S12: =MAX(bola02!E:E) -> 6 | T12: =MAX(bola03!E:E) -> 6 | U12: =MAX(bola04!E:E) -> 6 | V12: =MAX(bola05!E:E) -> 6 | W12: =MAX(bola06!E:E) -> 6
A13: 12 | B13: 27/05/1996 | C13: 4 | D13: 16 | E13: 19 | F13: 20 | G13: 27 | H13: 43 | I13: =RIGHT(("0"&C13),2)&RIGHT(("0"&D13),2)&RIGHT(("0"&E13),2)&RIGHT(("0"&F13),2)&RIGHT(("0"&G13),2)&RIGHT(("0"&H13),2) -> 041619202743 | J13: =COUNTIF(I:I,I13) -> 1 | K13: 0 | L13: =VLOOKUP(C13,bola01!A:E,5,0) -> 6 | M13: =VLOOKUP(D13,bola02!A:E,5,0) -> 3 | N13: =VLOOKUP(E13,bola03!A:E,5,0) -> 1 | O13: =VLOOKUP(F13,bola04!A:E,5,0) -> 2 | P13: =VLOOKUP(G13,bola05!A:E,5,0) -> 0 | Q13: =VLOOKUP(H13,bola06!A:E,5,0) -> 5 | R13: =MAX(bola01!E:E) -> 6 | S13: =MAX(bola02!E:E) -> 6 | T13: =MAX(bola03!E:E) -> 6 | U13: =MAX(bola04!E:E) -> 6 | V13: =MAX(bola05!E:E) -> 6 | W13: =MAX(bola06!E:E) -> 6
... A3005: 3004 | B3005: 05/05/2026 | C3005: 1 | D3005: 5 | E3005: 7 | F3005: 22 | G3005: 50 | H3005: 59 | I3005: =RIGHT(("0"&C3005),2)&RIGHT(("0"&D3005),2)&RIGHT(("0"&E3005),2)&RIGHT(("0"&F3005),2)&RIGHT(("0"&G3005),2)&RIGHT(("0"&H3005),2) -> 010507225059 | J3005: =COUNTIF(I:I,I3005) -> 1 | K3005: 0 | L3005: =VLOOKUP(C3005,bola01!A:E,5,0) -> 2 | M3005: =VLOOKUP(D3005,bola02!A:E,5,0) -> 5 | N3005: =VLOOKUP(E3005,bola03!A:E,5,0) -> 2 | O3005: =VLOOKUP(F3005,bola04!A:E,5,0) | P3005: =VLOOKUP(G3005,bola05!A:E,5,0) -> 0 | Q3005: =VLOOKUP(H3005,bola06!A:E,5,0) -> 5 | R3005: =MAX(bola01!E:E) -> 6 | S3005: =MAX(bola02!E:E) -> 6 | T3005: =MAX(bola03!E:E) -> 6 | U3005: =MAX(bola04!E:E) -> 6 | V3005: =MAX(bola05!E:E) -> 6 | W3005: =MAX(bola06!E:E) -> 6

Sheet nosso jogo
A1: 10 | B1: 22 | C1: 32 | D1: 39 | E1: 53 | F1: 59 | G1: =A1&B1&C1&D1&E1&F1 -> 102232395359
A2: 03 | B2: 18 | C2: 33 | D2: 41 | E2: 47 | F2: 50 | G2: =A2&B2&C2&D2&E2&F2 -> 031833414750
A3: 02 | B3: 14 | C3: 21 | D3: 38 | E3: 43 | F3: 48 | G3: =A3&B3&C3&D3&E3&F3 -> 021421384348
A4: 06 | B4: 12 | C4: 26 | D4: 27 | E4: 44 | F4: 57 | G4: =A4&B4&C4&D4&E4&F4 -> 061226274457
A5: 08 | B5: 09 | C5: 19 | D5: 34 | E5: 39 | F5: 53 | G5: =A5&B5&C5&D5&E5&F5 -> 080919343953
A6: 10 | B6: 19 | C6: 22 | D6: 37 | E6: 38 | F6: 57 | G6: =A6&B6&C6&D6&E6&F6 -> 101922373857
A7: 03 | B7: 15 | C7: 42 | D7: 47 | E7: 48 | F7: 55 | G7: =A7&B7&C7&D7&E7&F7 -> 031542474855
A8: 06 | B8: 18 | C8: 21 | D8: 32 | E8: 37 | F8: 43 | G8: =A8&B8&C8&D8&E8&F8 -> 061821323743
A9: 14 | B9: 25 | C9: 27 | D9: 33 | E9: 50 | F9: 59 | G9: =A9&B9&C9&D9&E9&F9 -> 142527335059
A10: 01 | B10: 08 | C10: 12 | D10: 26 | E10: 32 | F10: 39 | G10: =A10&B10&C10&D10&E10&F10 -> 010812263239
A11: 10 | B11: 18 | C11: 21 | D11: 26 | E11: 47 | F11: 53 | G11: =A11&B11&C11&D11&E11&F11 -> 101821264753
A12: 03 | B12: 22 | C12: 33 | D12: 39 | E12: 42 | F12: 50 | G12: =A12&B12&C12&D12&E12&F12 -> 032233394250
... A110: 10 | B110: 16 | C110: 22 | D110: 34 | E110: 48 | F110: 57 | G110: =A110&B110&C110&D110&E110&F110 -> 101622344857
A111: 04 | B111: 10 | C111: 16 | D111: 21 | E111: 26 | F111: 27 | G111: =A111&B111&C111&D111&E111&F111 -> 041016212627
A112: 09 | B112: 11 | C112: 17 | D112: 24 | E112: 29 | F112: 38 | G112: =A112&B112&C112&D112&E112&F112 -> 091117242938
A113: 12 | B113: 13 | C113: 15 | D113: 18 | E113: 20 | F113: 37 | G113: =A113&B113&C113&D113&E113&F113 -> 121315182037
A114: 25 | B114: 27 | C114: 34 | D114: 41 | E114: 44 | F114: 49 | G114: =A114&B114&C114&D114&E114&F114 -> 252734414449
A115: 14 | B115: 19 | C115: 35 | D115: 45 | E115: 54 | F115: 57 | G115: =A115&B115&C115&D115&E115&F115 -> 141935455457
A116: 10 | B116: 25 | C116: 28 | D116: 39 | E116: 40 | F116: 42 | G116: =A116&B116&C116&D116&E116&F116 -> 102528394042
A117: 04 | B117: 17 | C117: 24 | D117: 38 | E117: 47 | F117: 48 | G117: =A117&B117&C117&D117&E117&F117 -> 041724384748
A118: 11 | B118: 20 | C118: 29 | D118: 37 | E118: 50 | F118: 51 | G118: =A118&B118&C118&D118&E118&F118 -> 112029375051
A119: 13 | B119: 18 | C119: 26 | D119: 34 | E119: 41 | F119: 59 | G119: =A119&B119&C119&D119&E119&F119 -> 131826344159
A120: 09 | B120: 12 | C120: 21 | D120: 35 | E120: 52 | F120: 54 | G120: =A120&B120&C120&D120&E120&F120 -> 091221355254

Sheet bola01
A1: 2 | B1: - | C1: =COUNTIF('MEGA SENA'!C:C,A1) -> 270 | D1: =MOD(C1,(2+0+2+6)) -> 0 | E1: =IF(D1=0,"",MOD(C1,(3+4)))
A2: 6 | B2: - | C2: =COUNTIF('MEGA SENA'!C:C,A2) -> 190 | D2: =MOD(C2,(2+0+2+6)) -> 0 | E2: =IF(D2=0,"",MOD(C2,(3+4)))
A3: 14 | B3: - | C3: =COUNTIF('MEGA SENA'!C:C,A3) -> 80 | D3: =MOD(C3,(2+0+2+6)) -> 0 | E3: =IF(D3=0,"",MOD(C3,(3+4)))
A4: 18 | B4: - | C4: =COUNTIF('MEGA SENA'!C:C,A4) -> 40 | D4: =MOD(C4,(2+0+2+6)) -> 0 | E4: =IF(D4=0,"",MOD(C4,(3+4)))
A5: 40 | B5: - | C5: =COUNTIF('MEGA SENA'!C:C,A5) -> 0 | D5: =MOD(C5,(2+0+2+6)) -> 0 | E5: =IF(D5=0,"",MOD(C5,(3+4)))
A6: 42 | B6: - | C6: =COUNTIF('MEGA SENA'!C:C,A6) -> 0 | D6: =MOD(C6,(2+0+2+6)) -> 0 | E6: =IF(D6=0,"",MOD(C6,(3+4)))
A7: 44 | B7: - | C7: =COUNTIF('MEGA SENA'!C:C,A7) -> 0 | D7: =MOD(C7,(2+0+2+6)) -> 0 | E7: =IF(D7=0,"",MOD(C7,(3+4)))
A8: 45 | B8: - | C8: =COUNTIF('MEGA SENA'!C:C,A8) -> 0 | D8: =MOD(C8,(2+0+2+6)) -> 0 | E8: =IF(D8=0,"",MOD(C8,(3+4)))
A9: 47 | B9: - | C9: =COUNTIF('MEGA SENA'!C:C,A9) -> 0 | D9: =MOD(C9,(2+0+2+6)) -> 0 | E9: =IF(D9=0,"",MOD(C9,(3+4)))
A10: 48 | B10: - | C10: =COUNTIF('MEGA SENA'!C:C,A10) -> 0 | D10: =MOD(C10,(2+0+2+6)) -> 0 | E10: =IF(D10=0,"",MOD(C10,(3+4)))
A11: 49 | B11: - | C11: =COUNTIF('MEGA SENA'!C:C,A11) -> 0 | D11: =MOD(C11,(2+0+2+6)) -> 0 | E11: =IF(D11=0,"",MOD(C11,(3+4)))
A12: 51 | B12: - | C12: =COUNTIF('MEGA SENA'!C:C,A12) -> 0 | D12: =MOD(C12,(2+0+2+6)) -> 0 | E12: =IF(D12=0,"",MOD(C12,(3+4)))
... A60: 31 | B60: - | C60: =COUNTIF('MEGA SENA'!C:C,A60) -> 7 | D60: =MOD(C60,(2+0+2+6)) -> 7 | E60: =IF(D60=0,"",MOD(C60,(3+4))) -> 0

Sheet bola02
A1: 1 | B1: - | C1: =COUNTIF('MEGA SENA'!D:D,A1) -> 0 | D1: =MOD(C1,(2+0+2+6)) -> 0 | E1: =IF(D1=0,"",MOD(C1,(3+4)))
A2: 6 | B2: - | C2: =COUNTIF('MEGA SENA'!D:D,A2) -> 100 | D2: =MOD(C2,(2+0+2+6)) -> 0 | E2: =IF(D2=0,"",MOD(C2,(3+4)))
A3: 41 | B3: - | C3: =COUNTIF('MEGA SENA'!D:D,A3) -> 10 | D3: =MOD(C3,(2+0+2+6)) -> 0 | E3: =IF(D3=0,"",MOD(C3,(3+4)))
A4: 49 | B4: - | C4: =COUNTIF('MEGA SENA'!D:D,A4) -> 0 | D4: =MOD(C4,(2+0+2+6)) -> 0 | E4: =IF(D4=0,"",MOD(C4,(3+4)))
A5: 52 | B5: - | C5: =COUNTIF('MEGA SENA'!D:D,A5) -> 0 | D5: =MOD(C5,(2+0+2+6)) -> 0 | E5: =IF(D5=0,"",MOD(C5,(3+4)))
A6: 53 | B6: - | C6: =COUNTIF('MEGA SENA'!D:D,A6) -> 0 | D6: =MOD(C6,(2+0+2+6)) -> 0 | E6: =IF(D6=0,"",MOD(C6,(3+4)))
A7: 54 | B7: - | C7: =COUNTIF('MEGA SENA'!D:D,A7) -> 0 | D7: =MOD(C7,(2+0+2+6)) -> 0 | E7: =IF(D7=0,"",MOD(C7,(3+4)))
A8: 55 | B8: - | C8: =COUNTIF('MEGA SENA'!D:D,A8) -> 0 | D8: =MOD(C8,(2+0+2+6)) -> 0 | E8: =IF(D8=0,"",MOD(C8,(3+4)))
A9: 56 | B9: - | C9: =COUNTIF('MEGA SENA'!D:D,A9) -> 0 | D9: =MOD(C9,(2+0+2+6)) -> 0 | E9: =IF(D9=0,"",MOD(C9,(3+4)))
A10: 57 | B10: - | C10: =COUNTIF('MEGA SENA'!D:D,A10) -> 0 | D10: =MOD(C10,(2+0+2+6)) -> 0 | E10: =IF(D10=0,"",MOD(C10,(3+4)))
A11: 58 | B11: - | C11: =COUNTIF('MEGA SENA'!D:D,A11) -> 0 | D11: =MOD(C11,(2+0+2+6)) -> 0 | E11: =IF(D11=0,"",MOD(C11,(3+4)))
A12: 59 | B12: - | C12: =COUNTIF('MEGA SENA'!D:D,A12) -> 0 | D12: =MOD(C12,(2+0+2+6)) -> 0 | E12: =IF(D12=0,"",MOD(C12,(3+4)))
... A60: 44 | B60: - | C60: =COUNTIF('MEGA SENA'!D:D,A60) -> 7 | D60: =MOD(C60,(2+0+2+6)) -> 7 | E60: =IF(D60=0,"",MOD(C60,(3+4))) -> 0

Sheet bola03
A1: 1 | B1: - | C1: =COUNTIF('MEGA SENA'!E:E,A1) -> 0 | D1: =MOD(C1,(2+0+2+6)) -> 0 | E1: =IF(D1=0,"",MOD(C1,(3+4)))
A2: 2 | B2: - | C2: =COUNTIF('MEGA SENA'!E:E,A2) -> 0 | D2: =MOD(C2,(2+0+2+6)) -> 0 | E2: =IF(D2=0,"",MOD(C2,(3+4)))
A3: 11 | B3: - | C3: =COUNTIF('MEGA SENA'!E:E,A3) -> 60 | D3: =MOD(C3,(2+0+2+6)) -> 0 | E3: =IF(D3=0,"",MOD(C3,(3+4)))
A4: 57 | B4: - | C4: =COUNTIF('MEGA SENA'!E:E,A4) -> 0 | D4: =MOD(C4,(2+0+2+6)) -> 0 | E4: =IF(D4=0,"",MOD(C4,(3+4)))
A5: 58 | B5: - | C5: =COUNTIF('MEGA SENA'!E:E,A5) -> 0 | D5: =MOD(C5,(2+0+2+6)) -> 0 | E5: =IF(D5=0,"",MOD(C5,(3+4)))
A6: 59 | B6: - | C6: =COUNTIF('MEGA SENA'!E:E,A6) -> 0 | D6: =MOD(C6,(2+0+2+6)) -> 0 | E6: =IF(D6=0,"",MOD(C6,(3+4)))
A7: 60 | B7: - | C7: =COUNTIF('MEGA SENA'!E:E,A7) -> 0 | D7: =MOD(C7,(2+0+2+6)) -> 0 | E7: =IF(D7=0,"",MOD(C7,(3+4)))
A8: 6 | B8: - | C8: =COUNTIF('MEGA SENA'!E:E,A8) -> 13 | D8: =MOD(C8,(2+0+2+6)) -> 3 | E8: =IF(D8=0,"",MOD(C8,(3+4))) -> 6
A9: 32 | B9: - | C9: =COUNTIF('MEGA SENA'!E:E,A9) -> 104 | D9: =MOD(C9,(2+0+2+6)) -> 4 | E9: =IF(D9=0,"",MOD(C9,(3+4))) -> 6
A10: 33 | B10: - | C10: =COUNTIF('MEGA SENA'!E:E,A10) -> 83 | D10: =MOD(C10,(2+0+2+6)) -> 3 | E10: =IF(D10=0,"",MOD(C10,(3+4))) -> 6
A11: 34 | B11: - | C11: =COUNTIF('MEGA SENA'!E:E,A11) -> 104 | D11: =MOD(C11,(2+0+2+6)) -> 4 | E11: =IF(D11=0,"",MOD(C11,(3+4))) -> 6
A12: 36 | B12: - | C12: =COUNTIF('MEGA SENA'!E:E,A12) -> 69 | D12: =MOD(C12,(2+0+2+6)) -> 9 | E12: =IF(D12=0,"",MOD(C12,(3+4))) -> 6
... A60: 45 | B60: - | C60: =COUNTIF('MEGA SENA'!E:E,A60) -> 28 | D60: =MOD(C60,(2+0+2+6)) -> 8 | E60: =IF(D60=0,"",MOD(C60,(3+4))) -> 0

Sheet bola04
A1: 1 | B1: - | C1: =COUNTIF('MEGA SENA'!F:F,A1) -> 0 | D1: =MOD(C1,(2+0+2+6)) -> 0 | E1: =IF(D1=0,"",MOD(C1,(3+4)))
A2: 2 | B2: - | C2: =COUNTIF('MEGA SENA'!F:F,A2) -> 0 | D2: =MOD(C2,(2+0+2+6)) -> 0 | E2: =IF(D2=0,"",MOD(C2,(3+4)))
A3: 3 | B3: - | C3: =COUNTIF('MEGA SENA'!F:F,A3) -> 0 | D3: =MOD(C3,(2+0+2+6)) -> 0 | E3: =IF(D3=0,"",MOD(C3,(3+4)))
A4: 4 | B4: - | C4: =COUNTIF('MEGA SENA'!F:F,A4) -> 0 | D4: =MOD(C4,(2+0+2+6)) -> 0 | E4: =IF(D4=0,"",MOD(C4,(3+4)))
A5: 5 | B5: - | C5: =COUNTIF('MEGA SENA'!F:F,A5) -> 0 | D5: =MOD(C5,(2+0+2+6)) -> 0 | E5: =IF(D5=0,"",MOD(C5,(3+4)))
A6: 6 | B6: - | C6: =COUNTIF('MEGA SENA'!F:F,A6) -> 0 | D6: =MOD(C6,(2+0+2+6)) -> 0 | E6: =IF(D6=0,"",MOD(C6,(3+4)))
A7: 22 | B7: - | C7: =COUNTIF('MEGA SENA'!F:F,A7) -> 50 | D7: =MOD(C7,(2+0+2+6)) -> 0 | E7: =IF(D7=0,"",MOD(C7,(3+4)))
A8: 32 | B8: - | C8: =COUNTIF('MEGA SENA'!F:F,A8) -> 110 | D8: =MOD(C8,(2+0+2+6)) -> 0 | E8: =IF(D8=0,"",MOD(C8,(3+4)))
A9: 53 | B9: - | C9: =COUNTIF('MEGA SENA'!F:F,A9) -> 30 | D9: =MOD(C9,(2+0+2+6)) -> 0 | E9: =IF(D9=0,"",MOD(C9,(3+4)))
A10: 56 | B10: - | C10: =COUNTIF('MEGA SENA'!F:F,A10) -> 10 | D10: =MOD(C10,(2+0+2+6)) -> 0 | E10: =IF(D10=0,"",MOD(C10,(3+4)))
A11: 59 | B11: - | C11: =COUNTIF('MEGA SENA'!F:F,A11) -> 0 | D11: =MOD(C11,(2+0+2+6)) -> 0 | E11: =IF(D11=0,"",MOD(C11,(3+4)))
A12: 60 | B12: - | C12: =COUNTIF('MEGA SENA'!F:F,A12) -> 0 | D12: =MOD(C12,(2+0+2+6)) -> 0 | E12: =IF(D12=0,"",MOD(C12,(3+4)))
... A60: 55 | B60: - | C60: =COUNTIF('MEGA SENA'!F:F,A60) -> 14 | D60: =MOD(C60,(2+0+2+6)) -> 4 | E60: =IF(D60=0,"",MOD(C60,(3+4))) -> 0

Sheet bola05
A1: 1 | B1: - | C1: =COUNTIF('MEGA SENA'!G:G,A1) -> 0 | D1: =MOD(C1,(2+0+2+6)) -> 0 | E1: =IF(D1=0,"",MOD(C1,(3+4)))
A2: 2 | B2: - | C2: =COUNTIF('MEGA SENA'!G:G,A2) -> 0 | D2: =MOD(C2,(2+0+2+6)) -> 0 | E2: =IF(D2=0,"",MOD(C2,(3+4)))
A3: 3 | B3: - | C3: =COUNTIF('MEGA SENA'!G:G,A3) -> 0 | D3: =MOD(C3,(2+0+2+6)) -> 0 | E3: =IF(D3=0,"",MOD(C3,(3+4)))
A4: 4 | B4: - | C4: =COUNTIF('MEGA SENA'!G:G,A4) -> 0 | D4: =MOD(C4,(2+0+2+6)) -> 0 | E4: =IF(D4=0,"",MOD(C4,(3+4)))
A5: 5 | B5: - | C5: =COUNTIF('MEGA SENA'!G:G,A5) -> 0 | D5: =MOD(C5,(2+0+2+6)) -> 0 | E5: =IF(D5=0,"",MOD(C5,(3+4)))
A6: 6 | B6: - | C6: =COUNTIF('MEGA SENA'!G:G,A6) -> 0 | D6: =MOD(C6,(2+0+2+6)) -> 0 | E6: =IF(D6=0,"",MOD(C6,(3+4)))
A7: 7 | B7: - | C7: =COUNTIF('MEGA SENA'!G:G,A7) -> 0 | D7: =MOD(C7,(2+0+2+6)) -> 0 | E7: =IF(D7=0,"",MOD(C7,(3+4)))
A8: 8 | B8: - | C8: =COUNTIF('MEGA SENA'!G:G,A8) -> 0 | D8: =MOD(C8,(2+0+2+6)) -> 0 | E8: =IF(D8=0,"",MOD(C8,(3+4)))
A9: 9 | B9: - | C9: =COUNTIF('MEGA SENA'!G:G,A9) -> 0 | D9: =MOD(C9,(2+0+2+6)) -> 0 | E9: =IF(D9=0,"",MOD(C9,(3+4)))
A10: 10 | B10: - | C10: =COUNTIF('MEGA SENA'!G:G,A10) -> 0 | D10: =MOD(C10,(2+0+2+6)) -> 0 | E10: =IF(D10=0,"",MOD(C10,(3+4)))
A11: 13 | B11: - | C11: =COUNTIF('MEGA SENA'!G:G,A11) -> 0 | D11: =MOD(C11,(2+0+2+6)) -> 0 | E11: =IF(D11=0,"",MOD(C11,(3+4)))
A12: 34 | B12: - | C12: =COUNTIF('MEGA SENA'!G:G,A12) -> 60 | D12: =MOD(C12,(2+0+2+6)) -> 0 | E12: =IF(D12=0,"",MOD(C12,(3+4)))
... A60: 50 | B60: - | C60: =COUNTIF('MEGA SENA'!G:G,A60) -> 112 | D60: =MOD(C60,(2+0+2+6)) -> 2 | E60: =IF(D60=0,"",MOD(C60,(3+4))) -> 0

Sheet bola06
A1: 1 | B1: - | C1: =COUNTIF('MEGA SENA'!H:H,A1) -> 0 | D1: =MOD(C1,(2+0+2+6)) -> 0 | E1: =IF(D1=0,"",MOD(C1,(3+4)))
A2: 2 | B2: - | C2: =COUNTIF('MEGA SENA'!H:H,A2) -> 0 | D2: =MOD(C2,(2+0+2+6)) -> 0 | E2: =IF(D2=0,"",MOD(C2,(2+5)))
A3: 3 | B3: - | C3: =COUNTIF('MEGA SENA'!H:H,A3) -> 0 | D3: =MOD(C3,(2+0+2+6)) -> 0 | E3: =IF(D3=0,"",MOD(C3,(2+5)))
A4: 4 | B4: - | C4: =COUNTIF('MEGA SENA'!H:H,A4) -> 0 | D4: =MOD(C4,(2+0+2+6)) -> 0 | E4: =IF(D4=0,"",MOD(C4,(2+5)))
A5: 5 | B5: - | C5: =COUNTIF('MEGA SENA'!H:H,A5) -> 0 | D5: =MOD(C5,(2+0+2+6)) -> 0 | E5: =IF(D5=0,"",MOD(C5,(2+5)))
A6: 6 | B6: - | C6: =COUNTIF('MEGA SENA'!H:H,A6) -> 0 | D6: =MOD(C6,(2+0+2+6)) -> 0 | E6: =IF(D6=0,"",MOD(C6,(2+5)))
A7: 7 | B7: - | C7: =COUNTIF('MEGA SENA'!H:H,A7) -> 0 | D7: =MOD(C7,(2+0+2+6)) -> 0 | E7: =IF(D7=0,"",MOD(C7,(2+5)))
A8: 8 | B8: - | C8: =COUNTIF('MEGA SENA'!H:H,A8) -> 0 | D8: =MOD(C8,(2+0+2+6)) -> 0 | E8: =IF(D8=0,"",MOD(C8,(2+5)))
A9: 9 | B9: - | C9: =COUNTIF('MEGA SENA'!H:H,A9) -> 0 | D9: =MOD(C9,(2+0+2+6)) -> 0 | E9: =IF(D9=0,"",MOD(C9,(2+5)))
A10: 10 | B10: - | C10: =COUNTIF('MEGA SENA'!H:H,A10) -> 0 | D10: =MOD(C10,(2+0+2+6)) -> 0 | E10: =IF(D10=0,"",MOD(C10,(2+5)))
A11: 11 | B11: - | C11: =COUNTIF('MEGA SENA'!H:H,A11) -> 0 | D11: =MOD(C11,(2+0+2+6)) -> 0 | E11: =IF(D11=0,"",MOD(C11,(2+5)))
A12: 12 | B12: - | C12: =COUNTIF('MEGA SENA'!H:H,A12) -> 0 | D12: =MOD(C12,(2+0+2+6)) -> 0 | E12: =IF(D12=0,"",MOD(C12,(2+5)))
A13: 13 | B13: - | C13: =COUNTIF('MEGA SENA'!H:H,A13) -> 0 | D13: =MOD(C13,(2+0+2+6)) -> 0 | E13: =IF(D13=0,"",MOD(C13,(2+5)))
... A60: 53 | B60: - | C60: =COUNTIF('MEGA SENA'!H:H,A60) -> 182 | D60: =MOD(C60,(2+0+2+6)) -> 2 | E60: =IF(D60=0,"",MOD(C60,(2+5))) -> 0

Sheet meusjogos
A1: 2 | B1: 5 | C1: 10 | D1: 11 | E1: 14 | F1: 16 | G1: =RIGHT("0"&A1,2)&RIGHT("0"&B1,2)&RIGHT("0"&C1,2)&RIGHT("0"&D1,2)&RIGHT("0"&E1,2)&RIGHT("0"&F1,2) -> 020510111416 | H1: =VLOOKUP(A1,bola01!A:C,3,0) -> 270 | I1: =VLOOKUP(B1,bola02!A:C,3,0) -> 96 | J1: =VLOOKUP(C1,bola03!A:C,3,0) -> 44 | K1: =VLOOKUP(D1,bola04!A:C,3,0) -> 7 | L1: =VLOOKUP(E1,bola05!A:C,3,0) -> 1 | M1: =VLOOKUP(F1,bola06!A:C,3,0) -> 0
A2: 17 | B2: 18 | C2: 20 | D2: 21 | E2: 22 | F2: 24 | G2: =RIGHT("0"&A2,2)&RIGHT("0"&B2,2)&RIGHT("0"&C2,2)&RIGHT("0"&D2,2)&RIGHT("0"&E2,2)&RIGHT("0"&F2,2) -> 171820212224 | H2: =VLOOKUP(A2,bola01!A:C,3,0) -> 63 | I2: =VLOOKUP(B2,bola02!A:C,3,0) -> 123 | J2: =VLOOKUP(C2,bola03!A:C,3,0) -> 93 | K2: =VLOOKUP(D2,bola04!A:C,3,0) -> 47 | L2: =VLOOKUP(E2,bola05!A:C,3,0) -> 17 | M2: =VLOOKUP(F2,bola06!A:C,3,0) -> 2
A3: 25 | B3: 26 | C3: 27 | D3: 31 | E3: 32 | F3: 33 | G3: =RIGHT("0"&A3,2)&RIGHT("0"&B3,2)&RIGHT("0"&C3,2)&RIGHT("0"&D3,2)&RIGHT("0"&E3,2)&RIGHT("0"&F3,2) -> 252627313233 | H3: =VLOOKUP(A3,bola01!A:C,3,0) -> 22 | I3: =VLOOKUP(B3,bola02!A:C,3,0) -> 56 | J3: =VLOOKUP(C3,bola03!A:C,3,0) -> 98 | K3: =VLOOKUP(D3,bola04!A:C,3,0) -> 83 | L3: =VLOOKUP(E3,bola05!A:C,3,0) -> 54 | M3: =VLOOKUP(F3,bola06!A:C,3,0) -> 11
A4: 34 | B4: 38 | C4: 40 | D4: 41 | E4: 43 | F4: 45 | G4: =RIGHT("0"&A4,2)&RIGHT("0"&B4,2)&RIGHT("0"&C4,2)&RIGHT("0"&D4,2)&RIGHT("0"&E4,2)&RIGHT("0"&F4,2) -> 343840414345 | H4: =VLOOKUP(A4,bola01!A:C,3,0) -> 2 | I4: =VLOOKUP(B4,bola02!A:C,3,0) -> 12 | J4: =VLOOKUP(C4,bola03!A:C,3,0) -> 48 | K4: =VLOOKUP(D4,bola04!A:C,3,0) -> 117 | L4: =VLOOKUP(E4,bola05!A:C,3,0) -> 129 | M4: =VLOOKUP(F4,bola06!A:C,3,0) -> 69
A5: 47 | B5: 48 | C5: 50 | D5: 52 | E5: 54 | F5: 57 | G5: =RIGHT("0"&A5,2)&RIGHT("0"&B5,2)&RIGHT("0"&C5,2)&RIGHT("0"&D5,2)&RIGHT("0"&E5,2)&RIGHT("0"&F5,2) -> 474850525457 | H5: =VLOOKUP(A5,bola01!A:C,3,0) -> 0 | I5: =VLOOKUP(B5,bola02!A:C,3,0) -> 2 | J5: =VLOOKUP(C5,bola03!A:C,3,0) -> 12 | K5: =VLOOKUP(D5,bola04!A:C,3,0) -> 37 | L5: =VLOOKUP(E5,bola05!A:C,3,0) -> 94 | M5: =VLOOKUP(F5,bola06!A:C,3,0) -> 205
A6: 2 | B6: 18 | C6: 25 | D6: 32 | E6: 40 | F6: 47 | G6: =RIGHT("0"&A6,2)&RIGHT("0"&B6,2)&RIGHT("0"&C6,2)&RIGHT("0"&D6,2)&RIGHT("0"&E6,2)&RIGHT("0"&F6,2) -> 021825324047 | H6: =VLOOKUP(A6,bola01!A:C,3,0) -> 270 | I6: =VLOOKUP(B6,bola02!A:C,3,0) -> 123 | J6: =VLOOKUP(C6,bola03!A:C,3,0) -> 101 | K6: =VLOOKUP(D6,bola04!A:C,3,0) -> 110 | L6: =VLOOKUP(E6,bola05!A:C,3,0) -> 93 | M6: =VLOOKUP(F6,bola06!A:C,3,0) -> 84
A7: 5 | B7: 16 | C7: 21 | D7: 27 | E7: 33 | F7: 52 | G7: =RIGHT("0"&A7,2)&RIGHT("0"&B7,2)&RIGHT("0"&C7,2)&RIGHT("0"&D7,2)&RIGHT("0"&E7,2)&RIGHT("0"&F7,2) -> 051621273352 | H7: =VLOOKUP(A7,bola01!A:C,3,0) -> 215 | I7: =VLOOKUP(B7,bola02!A:C,3,0) -> 143 | J7: =VLOOKUP(C7,bola03!A:C,3,0) -> 87 | K7: =VLOOKUP(D7,bola04!A:C,3,0) -> 83 | L7: =VLOOKUP(E7,bola05!A:C,3,0) -> 68 | M7: =VLOOKUP(F7,bola06!A:C,3,0) -> 143
A8: 10 | B8: 17 | C8: 24 | D8: 31 | E8: 38 | F8: 54 | G8: =RIGHT("0"&A8,2)&RIGHT("0"&B8,2)&RIGHT("0"&C8,2)&RIGHT("0"&D8,2)&RIGHT("0"&E8,2)&RIGHT("0"&F8,2) -> 101724313854 | H8: =VLOOKUP(A8,bola01!A:C,3,0) -> 159 | I8: =VLOOKUP(B8,bola02!A:C,3,0) -> 122 | J8: =VLOOKUP(C8,bola03!A:C,3,0) -> 116 | K8: =VLOOKUP(D8,bola04!A:C,3,0) -> 83 | L8: =VLOOKUP(E8,bola05!A:C,3,0) -> 99 | M8: =VLOOKUP(F8,bola06!A:C,3,0) -> 187
A9: 11 | B9: 20 | C9: 26 | D9: 34 | E9: 43 | F9: 50 | G9: =RIGHT("0"&A9,2)&RIGHT("0"&B9,2)&RIGHT("0"&C9,2)&RIGHT("0"&D9,2)&RIGHT("0"&E9,2)&RIGHT("0"&F9,2) -> 112026344350 | H9: =VLOOKUP(A9,bola01!A:C,3,0) -> 106 | I9: =VLOOKUP(B9,bola02!A:C,3,0) -> 99 | J9: =VLOOKUP(C9,bola03!A:C,3,0) -> 95 | K9: =VLOOKUP(D9,bola04!A:C,3,0) -> 119 | L9: =VLOOKUP(E9,bola05!A:C,3,0) -> 129 | M9: =VLOOKUP(F9,bola06!A:C,3,0) -> 122
A10: 14 | B10: 22 | C10: 45 | D10: 48 | E10: 41 | F10: 57 | G10: =RIGHT("0"&A10,2)&RIGHT("0"&B10,2)&RIGHT("0"&C10,2)&RIGHT("0"&D10,2)&RIGHT("0"&E10,2)&RIGHT("0"&F10,2) -> 142245484157 | H10: =VLOOKUP(A10,bola01!A:C,3,0) -> 80 | I10: =VLOOKUP(B10,bola02!A:C,3,0) -> 82 | J10: =VLOOKUP(C10,bola03!A:C,3,0) -> 28 | K10: =VLOOKUP(D10,bola04!A:C,3,0) -> 42 | L10: =VLOOKUP(E10,bola05!A:C,3,0) -> 114 | M10: =VLOOKUP(F10,bola06!A:C,3,0) -> 205
A11: 2 | B11: 10 | C11: 16 | D11: 22 | E11: 33 | F11: 45 | G11: =RIGHT("0"&A11,2)&RIGHT("0"&B11,2)&RIGHT("0"&C11,2)&RIGHT("0"&D11,2)&RIGHT("0"&E11,2)&RIGHT("0"&F11,2) -> 021016223345 | H11: =VLOOKUP(A11,bola01!A:C,3,0) -> 270 | I11: =VLOOKUP(B11,bola02!A:C,3,0) -> 142 | J11: =VLOOKUP(C11,bola03!A:C,3,0) -> 79 | K11: =VLOOKUP(D11,bola04!A:C,3,0) -> 50 | L11: =VLOOKUP(E11,bola05!A:C,3,0) -> 68 | M11: =VLOOKUP(F11,bola06!A:C,3,0) -> 69
A12: 5 | B12: 11 | C12: 18 | D12: 25 | E12: 41 | F12: 52 | G12: =RIGHT("0"&A12,2)&RIGHT("0"&B12,2)&RIGHT("0"&C12,2)&RIGHT("0"&D12,2)&RIGHT("0"&E12,2)&RIGHT("0"&F12,2) -> 051118254152 | H12: =VLOOKUP(A12,bola01!A:C,3,0) -> 215 | I12: =VLOOKUP(B12,bola02!A:C,3,0) -> 138 | J12: =VLOOKUP(C12,bola03!A:C,3,0) -> 81 | K12: =VLOOKUP(D12,bola04!A:C,3,0) -> 77 | L12: =VLOOKUP(E12,bola05!A:C,3,0) -> 114 | M12: =VLOOKUP(F12,bola06!A:C,3,0) -> 143
... A32: 8 | B32: 10 | C32: 17 | D32: 31 | E32: 46 | F32: 53 | G32: =RIGHT("0"&A32,2)&RIGHT("0"&B32,2)&RIGHT("0"&C32,2)&RIGHT("0"&D32,2)&RIGHT("0"&E32,2)&RIGHT("0"&F32,2) -> 081017314653 | H32: =VLOOKUP(A32,bola01!A:C,3,0) -> 168 | I32: =VLOOKUP(B32,bola02!A:C,3,0) -> 142 | J32: =VLOOKUP(C32,bola03!A:C,3,0) -> 99 | K32: =VLOOKUP(D32,bola04!A:C,3,0) -> 83 | L32: =VLOOKUP(E32,bola05!A:C,3,0) -> 137 | M32: =VLOOKUP(F32,bola06!A:C,3,0) -> 182

Sheet Planilha10
A1: =+(7692.11*20)-((7692.11*20)*0.005)-((7692.11*20)*0.04) -> 146919.3
A2: 18000 | B2: 5.o
A3: 25000 | B3: doação
A4: 16000 | B4: itau
A5: =+1704*12 -> 20448 | B5: aluguel
A6: =A1-A2-A3-A4-A4 -> 71919.301 | B6: receita

Sheet Planilha11
A1: 5 | B1: 10 | C1: 15 | D1: 23 | E1: 24 | F1: 25 | G1: 364 | H1: 49 | I1: 54
A2: 5 | B2: 10 | C2: 11 | D2: 14 | E2: 16 | F2: 31 | G2: 43 | H2: 57 | I2: 58
A3: 4 | B3: 27 | C3: 38 | D3: 46 | E3: 47 | F3: 50 | G3: 51 | H3: 56 | I3: 59
A4: 6 | B4: 8 | C4: 32 | D4: 33 | E4: 37 | F4: 40 | G4: 41 | H4: 53 | I4: 56
A5: 1 | B5: 2 | C5: 3 | D5: 10 | E5: 11 | F5: 12 | G5: 27 | H5: 33 | I5: 56
A6: 3 | B6: 5 | C6: 24 | D6: 42 | E6: 52 | F6: 53 | G6: 54 | H6: 55 | I6: 57
A7: 1 | B7: 5 | C7: 6 | D7: 24 | E7: 26 | F7: 27 | G7: 47 | H7: 50 | I7: 55
A8: 4 | B8: 10 | C8: 11 | D8: 13 | E8: 14 | F8: 27 | G8: 37 | H8: 53 | I8: 56
A9: 6 | B9: 7 | C9: 8 | D9: 3 | E9: 19 | F9: 22 | G9: 51 | H9: 56 | I9: 60
A10: 6 | B10: 7 | C10: 14 | D10: 28 | E10: 41 | F10: 49 | G10: 52 | H10: 53 | I10: 56
A11: 2 | B11: 3 | C11: 12 | D11: 14 | E11: 23 | F11: 33 | G11: 34 | H11: 53 | I11: 60
A12: 7 | B12: 12 | C12: 16 | D12: 33 | E12: 40 | F12: 43 | G12: 46 | H12: 51 | I12: 55
... A98: 3 | B98: 5 | C98: 7 | D98: 10 | E98: 14 | F98: 37 | G98: 46 | H98: 58 | I98: 60
A99: 10 | B99: 12 | C99: 14 | D99: 24 | E99: 25 | F99: 33 | G99: 35 | H99: 37
A100: 5 | B100: 12 | C100: 34 | D100: 35 | E100: 42 | F100: 45 | G100: 56 | H100: 59
A101: 3 | B101: 7 | C101: 11 | D101: 32 | E101: 38 | F101: 56
A102: 3 | B102: 12 | C102: 25 | D102: 27 | E102: 30 | F102: 40 | G102: 46 | H102: 47 | I102: 60
A103: 5 | B103: 16 | C103: 27 | D103: 34 | E103: 45 | F103: 53 | G103: 55 | H103: 56 | I103: 58
A104: 4 | B104: 5 | C104: 10 | D104: 13 | E104: 25 | F104: 32 | G104: 46 | H104: 49 | I104: 60
A105: 2 | B105: 4 | C105: 8 | D105: 11 | E105: 12 | F105: 28 | G105: 35 | H105: 43 | I105: 49
A106: 7 | B106: 8 | C106: 14 | D106: 23 | E106: 34 | F106: 38 | G106: 46 | H106: 47 | I106: 51
A107: 5 | B107: 15 | C107: 26 | D107: 27 | E107: 30 | F107: 33 | G107: 41 | H107: 42 | I107: 54
A108: 10 | B108: 12 | C108: 23 | D108: 27 | E108: 33 | F108: 38 | G108: 47 | H108: 51 | I108: 52
A109: 2 | B109: 5 | C109: 10 | D109: 15 | E109: 24 | F109: 38 | G109: 49 | H109: 56 | I109: 57
A110: 2 | B110: 3 | C110: 14 | D110: 27 | E110: 28 | F110: 35 | G110: 50 | H110: 54 | I110: 57
A111: 5 | B111: 22 | C111: 23 | D111: 34 | E111: 45 | F111: 53 | G111: 56 | H111: 58 | I111: 60
A112: 1 | B112: 14 | C112: 33 | D112: 38 | E112: 49 | F112: 50 | G112: 53 | H112: 56 | I112: 59
A113: 8 | B113: 9 | C113: 12 | D113: 25 | E113: 38 | F113: 39 | G113: 41 | H113: 50 | I113: 60
... A167: 9 | B167: 13 | C167: 14 | D167: 16 | E167: 24 | F167: 27 | G167: 33 | H167: 34 | I167: 55
A168: 9 | B168: 11 | C168: 34 | D168: 35 | E168: 46 | F168: 57
A169: 11 | B169: 27 | C169: 41 | D169: 47 | E169: 56 | F169: 58
A170: 10 | B170: 13 | C170: 22 | D170: 34 | E170: 42 | F170: 60
A171: 4 | B171: 13 | C171: 14 | D171: 44 | E171: 49 | F171: 50 | G171: 54 | H171: 57 | I171: 60
A172: 6 | B172: 9 | C172: 11 | D172: 25 | E172: 34 | F172: 41 | G172: 44 | H172: 53 | I172: 57
A173: 16 | B173: 19 | C173: 20 | D173: 29 | E173: 35 | F173: 40 | G173: 53 | H173: 55 | I173: 60
A174: 11 | B174: 32 | C174: 41 | D174: 44 | E174: 48 | F174: 50 | G174: 54 | H174: 56 | I174: 57
A175: 10 | B175: 20 | C175: 22 | D175: 35 | E175: 40 | F175: 41 | G175: 42 | H175: 47 | I175: 53
A176: 9 | B176: 11 | C176: 12 | D176: 24 | E176: 31 | F176: 33 | G176: 42 | H176: 46 | I176: 60
A177: 9 | B177: 29 | C177: 31 | D177: 35 | E177: 40 | F177: 45 | G177: 50 | H177: 55 | I177: 56
A178: 5 | B178: 8 | C178: 24 | D178: 30 | E178: 33 | F178: 43 | G178: 46 | H178: 57 | I178: 60
...
